<?xml version="1.0" encoding="utf-8"?>
<!-- This URDF was automatically created by SolidWorks to URDF Exporter! Originally created by Stephen Brawner (brawner@gmail.com) 
     Commit Version: 1.6.0-4-g7f85cfe  Build Version: 1.6.7995.38578
     For more information, please see http://wiki.ros.org/sw_urdf_exporter -->
<robot
  name="truck_and_trailer">
  <link
    name="base_chassis_link">
    <inertial>
      <origin
        xyz="0.0723748257438112 -0.253997083929872 0.155225391142721"
        rpy="0 0 0" />
      <mass
        value="168.080262681343" />
      <inertia
        ixx="2.92523252098037"
        ixy="0.000218120184152512"
        ixz="-0.0366029956572545"
        iyy="11.0073196679447"
        iyz="1.94249868524719E-06"
        izz="13.0370029682555" />
    </inertial>
    <visual>
      <origin
        xyz="0 0 0"
        rpy="0 0 0" />
      <geometry>
        <mesh
          filename="package://truck_and_trailer/meshes/base_chassis_link.STL" />
      </geometry>
      <material
        name="">
        <color
          rgba="0.898039215686275 0.917647058823529 0.929411764705882 1" />
      </material>
    </visual>
    <collision>
      <origin
        xyz="0 0 0"
        rpy="0 0 0" />
      <geometry>
        <mesh
          filename="package://truck_and_trailer/meshes/base_chassis_link.STL" />
      </geometry>
    </collision>
  </link>
  <link
    name="rear_left_wheel_link">
    <inertial>
      <origin
        xyz="-4.98265708137602E-08 -6.00333797118324E-08 -9.36321333682155E-05"
        rpy="0 0 0" />
      <mass
        value="0.784079252834121" />
      <inertia
        ixx="0.00313877186753156"
        ixy="1.13845295642195E-08"
        ixz="3.73865756298406E-09"
        iyy="0.00313877014381181"
        iyz="3.01276205225292E-09"
        izz="0.00532754482672669" />
    </inertial>
    <visual>
      <origin
        xyz="0 0 0"
        rpy="0 0 0" />
      <geometry>
        <mesh
          filename="package://truck_and_trailer/meshes/rear_left_wheel_link.STL" />
      </geometry>
      <material
        name="">
        <color
          rgba="0.298039215686275 0.298039215686275 0.298039215686275 1" />
      </material>
    </visual>
    <collision>
      <origin
        xyz="0 0 0"
        rpy="0 0 0" />
      <geometry>
        <mesh
          filename="package://truck_and_trailer/meshes/rear_left_wheel_link.STL" />
      </geometry>
    </collision>
  </link>
  <joint
    name="rear_left_wheel_joint"
    type="continuous">
    <origin
      xyz="0 0 0.1016"
      rpy="1.5708 0 0" />
    <parent
      link="base_chassis_link" />
    <child
      link="rear_left_wheel_link" />
    <axis
      xyz="0 0 -1" />
    <limit
      effort="30"
      velocity="6" />
  </joint>
  <link
    name="rear_right_wheel_link">
    <inertial>
      <origin
        xyz="-7.25355551178808E-08 -2.94789359034375E-08 9.36317316124827E-05"
        rpy="0 0 0" />
      <mass
        value="0.784079220999345" />
      <inertia
        ixx="0.00313877685784208"
        ixy="9.80107157545839E-09"
        ixz="-4.00030025685091E-09"
        iyy="0.0031387651464266"
        iyz="-2.65238154905669E-09"
        izz="0.00532754482329061" />
    </inertial>
    <visual>
      <origin
        xyz="0 0 0"
        rpy="0 0 0" />
      <geometry>
        <mesh
          filename="package://truck_and_trailer/meshes/rear_right_wheel_link.STL" />
      </geometry>
      <material
        name="">
        <color
          rgba="0.298039215686275 0.298039215686275 0.298039215686275 1" />
      </material>
    </visual>
    <collision>
      <origin
        xyz="0 0 0"
        rpy="0 0 0" />
      <geometry>
        <mesh
          filename="package://truck_and_trailer/meshes/rear_right_wheel_link.STL" />
      </geometry>
    </collision>
  </link>
  <joint
    name="rear_right_wheel_joint"
    type="continuous">
    <origin
      xyz="0 -0.508 0.1016"
      rpy="1.5708 0 0" />
    <parent
      link="base_chassis_link" />
    <child
      link="rear_right_wheel_link" />
    <axis
      xyz="0 0 -1" />
    <limit
      effort="30"
      velocity="6" />
  </joint>
  <link
    name="trailer_n_hitch_link">
    <inertial>
      <origin
        xyz="-0.645634495412604 4.48147048309755E-06 0.198390881545613"
        rpy="0 0 0" />
      <mass
        value="327.423658075201" />
      <inertia
        ixx="6.92542289979725"
        ixy="0.00070660157794961"
        ixz="0.00456753205387379"
        iyy="28.8215763742987"
        iyz="3.35575598957988E-05"
        izz="27.8266803056134" />
    </inertial>
    <visual>
      <origin
        xyz="0 0 0"
        rpy="0 0 0" />
      <geometry>
        <mesh
          filename="package://truck_and_trailer/meshes/trailer_n_hitch_link.STL" />
      </geometry>
      <material
        name="">
        <color
          rgba="0.650980392156863 0.619607843137255 0.588235294117647 1" />
      </material>
    </visual>
    <collision>
      <origin
        xyz="0 0 0"
        rpy="0 0 0" />
      <geometry>
        <mesh
          filename="package://truck_and_trailer/meshes/trailer_n_hitch_link.STL" />
      </geometry>
    </collision>
  </link>
  <joint
    name="trailer_n_hitch_joint"
    type="revolute">
    <origin
      xyz="-0.44616 -0.254 0.1092"
      rpy="0 0 0" />
    <parent
      link="base_chassis_link" />
    <child
      link="trailer_n_hitch_link" />
    <axis
      xyz="0 0 -1" />
    <limit
      lower="-0.5236"
      upper="0.5236"
      effort="0"
      velocity="0" />
  </joint>
  <link
    name="trailer_front_left_wheel_link">
    <inertial>
      <origin
        xyz="-2.87841991353233E-08 7.28140389649745E-08 -9.36317316133639E-05"
        rpy="0 0 0" />
      <mass
        value="0.784079220999348" />
      <inertia
        ixx="0.00313876094299138"
        ixy="-5.40036667180988E-09"
        ixz="8.45046784124209E-10"
        iyy="0.0031387810612773"
        iyz="-4.72476729953416E-09"
        izz="0.00532754482329061" />
    </inertial>
    <visual>
      <origin
        xyz="0 0 0"
        rpy="0 0 0" />
      <geometry>
        <mesh
          filename="package://truck_and_trailer/meshes/trailer_front_left_wheel_link.STL" />
      </geometry>
      <material
        name="">
        <color
          rgba="1 1 1 0.35" />
      </material>
    </visual>
    <collision>
      <origin
        xyz="0 0 0"
        rpy="0 0 0" />
      <geometry>
        <mesh
          filename="package://truck_and_trailer/meshes/trailer_front_left_wheel_link.STL" />
      </geometry>
    </collision>
  </link>
  <joint
    name="trailer_front_left_wheel_joint"
    type="continuous">
    <origin
      xyz="-0.67438 0.2159 -0.0075981"
      rpy="1.5708 0 0" />
    <parent
      link="trailer_n_hitch_link" />
    <child
      link="trailer_front_left_wheel_link" />
    <axis
      xyz="0 0 -1" />
    <limit
      effort="30"
      velocity="6" />
  </joint>
  <link
    name="trailer_rear_left_wheel_link">
    <inertial>
      <origin
        xyz="7.8031524575195E-08 6.44170611296957E-09 -9.36317316133639E-05"
        rpy="0 0 0" />
      <mass
        value="0.78407922099935" />
      <inertia
        ixx="0.00313878236723469"
        ixy="-1.08849047848805E-09"
        ixz="-4.76686750060549E-09"
        iyy="0.00313875963703401"
        iyz="5.60806842823699E-10"
        izz="0.00532754482329062" />
    </inertial>
    <visual>
      <origin
        xyz="0 0 0"
        rpy="0 0 0" />
      <geometry>
        <mesh
          filename="package://truck_and_trailer/meshes/trailer_rear_left_wheel_link.STL" />
      </geometry>
      <material
        name="">
        <color
          rgba="1 1 1 0.35" />
      </material>
    </visual>
    <collision>
      <origin
        xyz="0 0 0"
        rpy="0 0 0" />
      <geometry>
        <mesh
          filename="package://truck_and_trailer/meshes/trailer_rear_left_wheel_link.STL" />
      </geometry>
    </collision>
  </link>
  <joint
    name="trailer_rear_left_wheel_joint"
    type="continuous">
    <origin
      xyz="-0.92838 0.2159 -0.0075981"
      rpy="1.5708 0 0" />
    <parent
      link="trailer_n_hitch_link" />
    <child
      link="trailer_rear_left_wheel_link" />
    <axis
      xyz="0 0 -1" />
    <limit
      effort="30"
      velocity="6" />
  </joint>
  <link
    name="trailer_front_right_wheel_link">
    <inertial>
      <origin
        xyz="-7.77130096940581E-08 -9.54476547798677E-09 9.36317316133596E-05"
        rpy="0 0 0" />
      <mass
        value="0.784079220999347" />
      <inertia
        ixx="0.00313878099612338"
        ixy="5.52000909405695E-09"
        ixz="-4.55353826437736E-09"
        iyy="0.00313876100814531"
        iyz="-1.51750431438814E-09"
        izz="0.00532754482329061" />
    </inertial>
    <visual>
      <origin
        xyz="0 0 0"
        rpy="0 0 0" />
      <geometry>
        <mesh
          filename="package://truck_and_trailer/meshes/trailer_front_right_wheel_link.STL" />
      </geometry>
      <material
        name="">
        <color
          rgba="1 1 1 0.35" />
      </material>
    </visual>
    <collision>
      <origin
        xyz="0 0 0"
        rpy="0 0 0" />
      <geometry>
        <mesh
          filename="package://truck_and_trailer/meshes/trailer_front_right_wheel_link.STL" />
      </geometry>
    </collision>
  </link>
  <joint
    name="trailer_front_right_wheel_joint"
    type="continuous">
    <origin
      xyz="-0.67438 -0.2159 -0.0075981"
      rpy="1.5708 0 0" />
    <parent
      link="trailer_n_hitch_link" />
    <child
      link="trailer_front_right_wheel_link" />
    <axis
      xyz="0 0 -1" />
    <limit
      effort="30"
      velocity="6" />
  </joint>
  <link
    name="trailer_rear_right_wheel_link">
    <inertial>
      <origin
        xyz="-6.14052209080285E-08 4.8577908751124E-08 9.36317316132538E-05"
        rpy="0 0 0" />
      <mass
        value="0.784079220999342" />
      <inertia
        ixx="0.0031387763997412"
        ixy="-1.00606241035101E-08"
        ixz="-4.2796927881452E-09"
        iyy="0.00313876560452747"
        iyz="2.17296105074814E-09"
        izz="0.0053275448232906" />
    </inertial>
    <visual>
      <origin
        xyz="0 0 0"
        rpy="0 0 0" />
      <geometry>
        <mesh
          filename="package://truck_and_trailer/meshes/trailer_rear_right_wheel_link.STL" />
      </geometry>
      <material
        name="">
        <color
          rgba="1 1 1 0.35" />
      </material>
    </visual>
    <collision>
      <origin
        xyz="0 0 0"
        rpy="0 0 0" />
      <geometry>
        <mesh
          filename="package://truck_and_trailer/meshes/trailer_rear_right_wheel_link.STL" />
      </geometry>
    </collision>
  </link>
  <joint
    name="trailer_rear_right_wheel_joint"
    type="continuous">
    <origin
      xyz="-0.92838 -0.2159 -0.0075981"
      rpy="1.5708 0 0" />
    <parent
      link="trailer_n_hitch_link" />
    <child
      link="trailer_rear_right_wheel_link" />
    <axis
      xyz="0 0 -1" />
    <limit
      effort="30"
      velocity="6" />
  </joint>
  <link
    name="front_left_wheel_revolute_link">
    <inertial>
      <origin
        xyz="1.22124532708767E-15 0.0441998322829882 -0.042510111403507"
        rpy="0 0 0" />
      <mass
        value="0.200576881049191" />
      <inertia
        ixx="0.000369683498051665"
        ixy="-1.1118705425367E-18"
        ixz="2.32830724824954E-19"
        iyy="5.18373707811601E-05"
        iyz="6.64392826806987E-05"
        izz="0.000332287662706047" />
    </inertial>
    <visual>
      <origin
        xyz="0 0 0"
        rpy="0 0 0" />
      <geometry>
        <mesh
          filename="package://truck_and_trailer/meshes/front_left_wheel_revolute_link.STL" />
      </geometry>
      <material
        name="">
        <color
          rgba="0.898039215686275 0.917647058823529 0.929411764705882 1" />
      </material>
    </visual>
    <collision>
      <origin
        xyz="0 0 0"
        rpy="0 0 0" />
      <geometry>
        <mesh
          filename="package://truck_and_trailer/meshes/front_left_wheel_revolute_link.STL" />
      </geometry>
    </collision>
  </link>
  <joint
    name="front_left_wheel_revolute_joint"
    type="revolute">
    <origin
      xyz="0.508 -0.12065 0.1516"
      rpy="0 0 0" />
    <parent
      link="base_chassis_link" />
    <child
      link="front_left_wheel_revolute_link" />
    <axis
      xyz="0 0 -1" />
    <limit
      lower="-0.26"
      upper="0.66"
      effort="0"
      velocity="0" />
  </joint>
  <link
    name="front_left_wheel_link">
    <inertial>
      <origin
        xyz="-2.56660643849216E-08 7.39707209373996E-08 -9.36317316135304E-05"
        rpy="0 0 0" />
      <mass
        value="0.784079220999347" />
      <inertia
        ixx="0.0031387605210159"
        ixy="-4.5273030827229E-09"
        ixz="6.43639443948284E-10"
        iyy="0.0031387814832528"
        iyz="-4.75639131646933E-09"
        izz="0.00532754482329061" />
    </inertial>
    <visual>
      <origin
        xyz="0 0 0"
        rpy="0 0 0" />
      <geometry>
        <mesh
          filename="package://truck_and_trailer/meshes/front_left_wheel_link.STL" />
      </geometry>
      <material
        name="">
        <color
          rgba="0.298039215686275 0.298039215686275 0.298039215686275 1" />
      </material>
    </visual>
    <collision>
      <origin
        xyz="0 0 0"
        rpy="0 0 0" />
      <geometry>
        <mesh
          filename="package://truck_and_trailer/meshes/front_left_wheel_link.STL" />
      </geometry>
    </collision>
  </link>
  <joint
    name="front_left_wheel_joint"
    type="continuous">
    <origin
      xyz="0 0.1207 -0.05"
      rpy="1.5708 0 0" />
    <parent
      link="front_left_wheel_revolute_link" />
    <child
      link="front_left_wheel_link" />
    <axis
      xyz="0 0 -1" />
    <limit
      effort="30"
      velocity="6" />
  </joint>
  <link
    name="front_right_wheel_revolute_link">
    <inertial>
      <origin
        xyz="1.66533453693773E-15 -0.0441998322829901 -0.0425101114035069"
        rpy="0 0 0" />
      <mass
        value="0.200576881049191" />
      <inertia
        ixx="0.000369683498051665"
        ixy="-1.78997664883669E-19"
        ixz="-6.01526521430623E-20"
        iyy="5.183737078116E-05"
        iyz="-6.64392826806986E-05"
        izz="0.000332287662706047" />
    </inertial>
    <visual>
      <origin
        xyz="0 0 0"
        rpy="0 0 0" />
      <geometry>
        <mesh
          filename="package://truck_and_trailer/meshes/front_right_wheel_revolute_link.STL" />
      </geometry>
      <material
        name="">
        <color
          rgba="0.898039215686275 0.917647058823529 0.929411764705882 1" />
      </material>
    </visual>
    <collision>
      <origin
        xyz="0 0 0"
        rpy="0 0 0" />
      <geometry>
        <mesh
          filename="package://truck_and_trailer/meshes/front_right_wheel_revolute_link.STL" />
      </geometry>
    </collision>
  </link>
  <joint
    name="front_right_wheel_revolute_joint"
    type="revolute">
    <origin
      xyz="0.508 -0.38735 0.1516"
      rpy="0 0 0" />
    <parent
      link="base_chassis_link" />
    <child
      link="front_right_wheel_revolute_link" />
    <axis
      xyz="0 0 -1" />
    <limit
      lower="-0.66"
      upper="0.26"
      effort="0"
      velocity="0" />
    <safety_controller
      soft_upper_limit="0.243"
      soft_lower_limit="-0.603"
      k_position="100"
      k_velocity="0" />
  </joint>
  <link
    name="front_right_wheel_link">
    <inertial>
      <origin
        xyz="-7.68976591292159E-08 1.47364998537292E-08 9.36317316134194E-05"
        rpy="0 0 0" />
      <mass
        value="0.784079220999348" />
      <inertia
        ixx="0.00313878233921512"
        ixy="-1.3494135471091E-09"
        ixz="-4.79949634266101E-09"
        iyy="0.00313875966505358"
        iyz="-4.86308105339538E-11"
        izz="0.00532754482329062" />
    </inertial>
    <visual>
      <origin
        xyz="0 0 0"
        rpy="0 0 0" />
      <geometry>
        <mesh
          filename="package://truck_and_trailer/meshes/front_right_wheel_link.STL" />
      </geometry>
      <material
        name="">
        <color
          rgba="1 1 1 0.35" />
      </material>
    </visual>
    <collision>
      <origin
        xyz="0 0 0"
        rpy="0 0 0" />
      <geometry>
        <mesh
          filename="package://truck_and_trailer/meshes/front_right_wheel_link.STL" />
      </geometry>
    </collision>
  </link>
  <joint
    name="front_right_wheel_joint"
    type="continuous">
    <origin
      xyz="0 -0.1207 -0.05"
      rpy="1.5708 0 0" />
    <parent
      link="front_right_wheel_revolute_link" />
    <child
      link="front_right_wheel_link" />
    <axis
      xyz="0 0 -1" />
    <limit
      effort="30"
      velocity="6" />
  </joint>
  <link
    name="lidar_mount_link">
    <inertial>
      <origin
        xyz="0 0 0.000254"
        rpy="0 0 0" />
      <mass
        value="0.11487" />
      <inertia
        ixx="8.3781E-05"
        ixy="-4.0887E-21"
        ixz="1.1001E-21"
        iyy="8.3781E-05"
        iyz="4.0733E-22"
        izz="0.00014238" />
    </inertial>
    <visual>
      <origin
        xyz="0 0 0"
        rpy="0 0 0" />
      <geometry>
        <mesh
          filename="package://truck_and_trailer/meshes/lidar_mount_link.STL" />
      </geometry>
      <material
        name="">
        <color
          rgba="1 1 1 1" />
      </material>
    </visual>
    <collision>
      <origin
        xyz="0 0 0"
        rpy="0 0 0" />
      <geometry>
        <mesh
          filename="package://truck_and_trailer/meshes/lidar_mount_link.STL" />
      </geometry>
    </collision>
  </link>
  <joint
    name="lidar_mount_fixed_joint"
    type="fixed">
    <origin
      xyz="0.097672 -0.254 0.4691"
      rpy="0 0 0" />
    <parent
      link="base_chassis_link" />
    <child
      link="lidar_mount_link" />
    <axis
      xyz="0 0 0" />
  </joint>
</robot>